Workbook

Sheet Sheet1
A1: S No. | B1: Name | C1: Date of birth | D1: Place of birth | E1: File No | F1: Sex | G1: Name of Father | H1: Name of Mother | I1: Fathers passport No | J1: Registration date | K1: ADD 1 | L1: ADD 2 | M1: ADD 3 | N1: MHA_File_No | O1: MHA_Date
A2: 1400 | B2: SHRIJEET SARANG HINGASPURE | C2: 45851 | D2: PARKVILLE, AUSTRALIA | E2: AU2065646519525 | F2: M | G2: SARANG SANJAY HINGASPURE | H2: PAYAL ARUN GULHANE | I2: (N8376462) | J2: 45880 | K2: PLOT NO 41 VIVEKANAND COLONY,RUKHMINI NAGAR | L2: AMRAVATI,AMRAVATI CITY | M2: PIN:444606,MAHARASHTRA,INDIA | N2: 202509055366 | O2: 45875
A3: 1401 | B3: IZHAAN MOHAMMED SHAIK | C3: 45820 | D3: WERIBEE, AUSTRALIA | E3: AU206564652032 | F3: M | G3: ABDUL ASIF | H3: SANIA ANJUM SHAIK | I3: (N4982081) | J3: 45880 | K3: 9-60-60,SUBBARAO STREET | L3: ISLAMPET,VIJAYAWADA,NTR DISTRICT | M3: PIN:520001,ANDHRA PRADESH,INDIA | N3: 202509053616 | O3: 45869
A4: 1402 | B4: MEHAR DAMANI | C4: 45730 | D4: ST ALBANS, AUSTRALIA | E4: AU2065646520525 | F4: F | G4: JAI KISHAN | H4: JYOTI | I4: (R8807909) | J4: 45880 | K4: WARD NO.5 | L4: PADAMPUR,SRI GANGANAGAR | M4: PIN:335041,RAJASTHAN,INDIA | N4: 202509051511 | O4: 45861
A5: 1403 | B5: ZOHAN VANIB MANSURI | C5: 45855 | D5: HOBART, AUSTRALIA | E5: AU2065646520925 | F5: M | G5: VANIB MOHMEDHARUN MANSURI | H5: RIZA VANIB MANSURI | I5: (T2762446) | J5: 45880 | K5: 74 MAULANA AZAD PARK SOC.,OPP AEGRO PETROL PUMP | L5: SARKHEJ ROAD,JUHAPURA,AHMEDABAD | M5: PIN:380055,GUJARAT,INDIA | N5: 202509053619 | O5: 45869
A6: 1404 | B6: ARJAN SINGH SEKHON | C6: 45770 | D6: WERRIBEE, AUSTRALIA | E6: AU2065646521325 | F6: M | G6: HARKAMALPREET SINGH | H6: ARSHPREET KAUR | I6: (Y6938892) | J6: 45880 | K6: VILLAGE DHENTHAL | L6: TEHSIL SAMANA,PATIALA | M6: PIN:147101,PUNJAB,INDIA | N6: 202509041249 | O6: 45824
A7: 1405 | B7: LOKESH CHOWDARY JAMMIGUMPULA | C7: 45803 | D7: BACCHUS MARSH, AUSTRALIA | E7: AU2065646521525 | F7: M | G7: HARIKRISHNA JAMMIGUMPULA | H7: NAVYA VADLAMUDI | I7: (N6471669) | J7: 45880 | K7: H.NO: 3-54,KOTHAPALEM VILLAGE | L7: MACHAVARAM MD,PALNADU | M7: PIN:522435,ANDHRA PRADESH,INDIA | N7: 202509055812 | O7: 45877
A8: 1406 | B8: AAYRA VERMA | C8: 45693 | D8: EPPING, AUSTRALIA | E8: AU2065649408125 | F8: F | G8: PARAMJIT SINGH | H8: ARTI | I8: (R5012661) | J8: 45883 | K8: H NO 20 | L8: UKSI JATTAN TEH RAJPURA,PATIALA | M8: PIN:140401,PUNJAB,INDIA | N8: 202509042789 | O8: 45829
A9: 1407 | B9: VANDAN MIHIRKUMAR PAREKH | C9: 45640 | D9: CLAYTON, AUSTRALIA | E9: AU2065649408725 | F9: M | G9: MIHIRKUMAR NIRANJANKUMAR PAREKH | H9: URVISHABEN MIHIRKUMAR PAREKH | I9: (P9563920) | J9: 45883 | K9: B/9 SATKARPARK SOCIETY RAMTALAWADI ROAD | L9: NADIAD,KHEDA | M9: PIN:387002,GUJARAT,INDIA | N9: 202509055846 | O9: 45877
A10: 1408 | B10: PRABHDOOR SINGH KHALSA | C10: 45818 | D10: HOBART, AUSTRALIA | E10: AU2065649409125 | F10: M | G10: GURSEWAK SINGH | H10: RAMANJIT KAUR | I10: (U0254730) | J10: 45883 | K10: V.P.O | L10: NANDA CHAUR,HOSHIARPUR | M10: PIN:146114,PUNJAB,INDIA | N10: 202509053355 | O10: 45868
A11: 1409 | B11: AJIT SINGH SIDHU | C11: 45614 | D11: ST SLBANS, AUSTRALIA | E11: AU2065649409725 | F11: M | G11: SHAGANDEEP SINGH SIDHU | H11: BAVANPREET KAUR | I11: (X3343149) | J11: 45883 | K11: V.P.O QILA HAKIMA | L11: DHURI,SANGRUR | M11: PIN:148034,PUNJAB,INDIA | N11: 202509044804 | O11: 45836
A12: 1410 | B12: SEHBAZ SINGH | C12: 45787 | D12: ST ALBANS, AUSTRALIA | E12: AU2065649409925 | F12: M | G12: HARPREET SINGH | H12: REENA TALWAR | I12: (S5192239) | J12: 45883 | K12: VPO JANDIALA ,PATTI RAM KI | L12: TEH. PHILLAUR,JALANDHAR | M12: PIN:144033,PUNJAB,INDIA | N12: 202509052252 | O12: 45864
A13: 1411 | B13: SHAIVI JAGLAN | C13: 45677 | D13: EPPING, AUSTRALIA | E13: AU2065649410725 | F13: F | G13: SUMIT KUMAR | H13: VEENITA RAJ | I13: (U3235472) | J13: 45883 | K13: VPO KURANA(54) | L13: ISRANA,PANIPAT | M13: PIN:132107,HARYANA,INDIA | N13: 202509041529 | O13: 45825
... A72: 1470 | B72: GURASEES KAUR | C72: 45841 | D72: BERWICK, AUSTRALIA | E72: AU2065655250325 | F72: F | G72: MALKEET SINGH | H72: MANDEEP KAUR | I72: U0125373 | J72: 45890 | K72: V.P.O LADHEWAL | L72: TEH AND DISTT,AMRITSAR | M72: PIN:143107,PUNJAB,INDIA | N72: 202509057521 | O72: 45884
A73: 1471 | B73: VYOM JAIMINKUMAR PATEL | C73: 21/07/2025 | D73: BERWICK, AUSTRALIA | E73: AU2065655250725 | F73: M | G73: JAIMINKUMAR KANUBHAI PATEL | H73: KOMALBAHEN JAIMINKUMAR PATEL | I73: X4319626 | J73: 45890 | K73: D1-104,FORTUNE AMPIRE,BORISANA ROAD | L73: KALOL,GANDHINAGAR | M73: PIN:382721,GUJARAT,INDIA | N73: 202509056059 | O73: 45878
A74: 1472 | B74: ZORAWAR SINGH SUBEDAR | C74: 45735 | D74: CANBERRA ACT, AUSTRALIA | E74: AU2065655251525 | F74: M | G74: PARDEEP SINGH | H74: TALJINDER KAUR | I74: S8555609 | J74: 45890 | K74: VILL JATI MAJRA | L74: PO HIMTANA TEH DHURI DISTT,SANGRUR | M74: PIN:148023,PUNJAB,INDIA | N74: 202509057403 | O74: 45883
A75: 1473 | B75: SARAH MARIAM RICHY | C75: 45639 | D75: HOBART, AUSTRALIA | E75: AU2065656456925 | F75: F | G75: RICHY ALEX MATHEW | H75: CHRISTINA MATHEWS | I75: S6910969 | J75: 45891 | K75: CHEERAMATTATHU HOUSE,PUNNAVELI PO | L75: MULAYAMVELI,NEDUMKUNNAM,KOTTAYAM | M75: PIN:689589,KERALA,INDIA | N75: 202509054889 | O75: 45874
A76: 1474 | B76: PAVIT KAUR SANDHU | C76: 30/05/2025 | D76: WERRIBEE, AUSTRALIA | E76: AU2065656457125 | F76: F | G76: ARPANDEEP SINGH SANDHU | H76: NAVJOT KAUR SANDHU | I76: P4243544 | J76: 45891 | K76: VILL MAUJGARH | L76: PO KAILA,MOGA | M76: PIN:142042,PUNJAB,INDIA | N76: 202509055178 | O76: 45875
A77: 1475 | B77: RAUNAK KAUR | C77: 45804 | D77: FRANKSTON, AUSTRALIA | E77: AU2065656457325 | F77: F | G77: PARAMJEET SINGH | H77: PARMINDER KAUR | I77: U6991388 | J77: 45891 | K77: VPO KHAIRA | L77: TEHSIL PHILLAUR,JALANDHAR | M77: PIN:144410,PUNJAB,INDIA | N77: 202509049235 | O77: 45853
A78: 1476 | B78: MISHA PATEL | C78: 45732 | D78: BALLARAT CENTRAL, AUSTRALIA | E78: AU2065656457525 | F78: F | G78: HARSH ASHWINKUMAR PATEL | H78: MITWA HEMANTBHAI JOSHI | I78: V8383506 | J78: 45891 | K78: 3 NITYANANDINI SOCIETY PART-1 | L78: GHATLODIA,AHMEDABAD | M78: PIN:380061,GUJARAT,INDIA | N78: 202509051431 | O78: 45861
A79: 1477 | B79: NADAR KAUR | C79: 45797 | D79: WERRIBEE, AUSTRALIA | E79: AU2065656457725 | F79: F | G79: MALKIT SINGH | H79: EMANPREET KAUR | I79: S7294995 | J79: 45891 | K79: VILL SANGRAI PO PANJGRAIN | L79: TEHSIL BATALA,GURDASPUR | M79: PIN:143505,PUNJAB,INDIA | N79: 202509056672 | O79: 45881
A80: 1478 | B80: AVY SINGH | C80: 45800 | D80: EPPING VICTORIA, AUSTRALIA | E80: AU2065656457925 | F80: M | G80: DAWINDER SINGH | H80: PARMINDER KAUR | I80: W7797834 | J80: 45891 | K80: VILL. PANDORI LUBANA | L80: PO PANDORI WARRAICH,AMRITSAR | M80: PIN:143008,PUNJAB,INDIA | N80: 202509056973 | O80: 45882
A81: 1479 | B81: VIHA JANJIRALA | C81: 45712 | D81: WESTMEAD, AUSTRALIA | E81: AU2065656458325 | F81: F | G81: SHIVA JANJIRALA | H81: VAISHNAVI DESHAMONI | I81: X4314692 | J81: 45891 | K81: H NO 19-1-529 UMDA BAZAR | L81: DOODH BOWLI,HYDERABAD | M81: PIN:500064,TELANGANA,INDIA | N81: 202509054585 | O81: 45873
A82: 1480 | B82: SIDIKSHA SHIVAPRASAD | C82: 45767 | D82: GEELONG, AUSTRALIA | E82: AU2065656458725 | F82: F | G82: SHIVAPRASAD MALLAPPA HOLAGUNDI | H82: CHAITRA IRANI SHETTRU | I82: S6335181 | J82: 45891 | K82: 1556/57,1ST MAIN,15TH CROSS,VINOBHANAGARA | L82: DAVANGERE,DAVANGERE | M82: PIN:577006,KARNATAKA,INDIA | N82: 202509058013 | O82: 45887
A83: 1481 | B83: AJOONI KAUR | C83: 45806 | D83: GEELONG, AUSTRALIA | E83: AU2065656458925 | F83: F | G83: DAVINDER SINGH | H83: LOVEPREET KAUR | I83: V9118008 | J83: 45891 | K83: 37 KAILASH PURI COLONY ALOHRAN GATE | L83: NABHA,PATIALA | M83: PIN:147201,PUNJAB,INDIA | N83: 202509041591 | O83: 45825
A84: 1482 | B84: SUKHRAJ KAUR | C84: 45770 | D84: PARKVILLE, AUSTRALIA | E84: AU2065656459325 | F84: F | G84: KARANBIR SINGH | H84: DIKSHA CHAUDHARY | I84: W1159646 | J84: 45891 | K84: HOUSE NO. 1226/1 | L84: SECTOR 19B,CHANDIGARH | M84: PIN:160009,CHANDIGARH,INDIA | N84: 202509047420 | O84: 45846
A85: 1483 | B85: AVITAAZ SINGH GARCHA | C85: 45840 | D85: BACCHUS MARSH MELBOURNE, AUSTRALIA | E85: AU2065656459725 | F85: M | G85: CHARANJOT SINGH | H85: MUSKANPREET KAUR | I85: S4137450 | J85: 45891 | K85: VILL KOTLI KHAKHIAN | L85: PO MANDHALI,JALANDHAR | M85: PIN:144502,PUNJAB,INDIA | N85: 202509051448 | O85: 45861
A86: 1484 | B86: HARLEEN KAUR MAHAL | C86: 45823 | D86: SHEPPARTON, AUSTRALIA | E86: AU2065656459925 | F86: F | G86: IQBAL SINGH MAHAL | H86: JAGROOP KAUR | I86: S7040407 | J86: 45891 | K86: VILL BHAGWANPUR PATTI MAHAL PO KOTLI SURAT MALHI | L86: TEH DERA BABA NANAK,GURDASPUR | M86: PIN:143605,PUNJAB,INDIA | N86: 202509054849 | O86: 45874
A87: 1485 | B87: IMAANVIR SINGH PABLA | C87: 45822 | D87: WERRIBEE, AUSTRALIA | E87: AU2065656460125 | F87: M | G87: GURPREET SINGH | H87: HARKAMAL KAUR | I87: V8389481 | J87: 45891 | K87: NEAR MELA SINGH KARYANA STORE | L87: LANGROYA,SBS NAGAR | M87: PIN:144516,PUNJAB,INDIA | N87: 202509056625 | O87: 45881
A88: 1486 | B88: PARV SAINI | C88: 45649 | D88: MOUNT WAVERLEY, AUSTRALIA | E88: AU2065656460325 | F88: M | G88: VIKAS | H88: SIMRANJEET KAUR | I88: V9557591 | J88: 45891 | K88: VILLAGE AURANGABAD | L88: TEHSIL JAGADHRI,YAMUNANAGAR | M88: PIN:135001,HARYANA,INDIA | N88: 202509053281 | O88: 45868
A89: 1487 | B89: AMBER KAUR RANDHAWA | C89: 45790 | D89: ST ALBANS, AUSTRALIA | E89: AU2065656485125 | F89: F | G89: MANRAJ SINGH | H89: JOBANJIT KAUR | I89: V9057277 | J89: 45891 | K89: 5 | L89: NIJAM PURA HAULIAN,AMRITSAR | M89: PIN:143603,PUNJAB,INDIA | N89: 202509042914 | O89: 45829
A90: 1488 | B90: RANBIR SINGH | C90: 45601 | D90: EPPING, AUSTRALIA | E90: AU2065656485525 | F90: M | G90: RUPINDERJIT SINGH | H90: VEERPAL KOUR | I90: N1453845 | J90: 45891 | K90: VPO SIKHWALA | L90: TEHSIL MALOUT,SRI MUKTSAR SAHIB | M90: PIN:152113,PUNJAB,INDIA | N90: 202509057647 | O90: 45885
A91: 1489 | B91: ARZAAN AHMED OSMAN | C91: 45742 | D91: WERRIBEE, AUSTRALIA | E91: AU2065656486125 | F91: M | G91: ASRAR AHMED AHSAN | H91: FABIHA SULTANA | I91: W7044038 | J91: 45891 | K91: 17-2-181/77 WAHED COLONY | L91: YAKUTPURA,HYDERABAD | M91: PIN:500023,TELANGANA,INDIA | N91: 202509056462 | O91: 45880
A92: 1490 | B92: ZORAWAR SINGH MANES | C92: 45821 | D92: WERRIBEE, AUSTRALIA | E92: AU2065656486525 | F92: M | G92: MANDEEP SINGH MANES | H92: KAMALPREET KAUR | I92: V7486587 | J92: 45891 | K92: DHARAMKOT ROAD,NEAR BABA ISHER SINGH COLLEGE | L92: VPO. KOT ISE KHAN,MOGA | M92: PIN:142043,PUNJAB,INDIA | N92: 202509056617 | O92: 45881
A93: 1491 | B93: SIARA MAHARJAN SINGH | C93: 45838 | D93: GEELONG, AUSTRALIA | E93: AU2065656546325 | F93: F | G93: SUKHPREET SINGH | H93: PRIYANKA MAHARJAN | I93: W7810573 | J93: 45891 | K93: HNO 3296/7 BASANT NAGAR | L93: ROPAR,ROPAR | M93: PIN:140001,PUNJAB,INDIA | N93: 202509058605 | O93: 45889
A94: 1492 | B94: HAYZEL JOSEPH | C94: 45812 | D94: BALLARAT, AUSTRALIA | E94: AU2065656549125 | F94: F | G94: RAKESH PARANTHARA VASU | H94: NEETHU RAKESH | I94: P0466228 | J94: 45891 | K94: PARANTHARA HOUSE | L94: CHAMPAKARA P.O,KARUKACHAL,KOTTAYAM | M94: PIN:686540,KERALA,INDIA | N94: 202509054593 | O94: 45873
A95: 1493 | B95: MIR SEHBHAAG KAUR SIDHU | C95: 45691 | D95: EPPING, AUSTRALIA | E95: AU2065656551125 | F95: F | G95: SUKHPREET SINGH SIDHU | H95: KULDEEP KAUR | I95: Y8071306 | J95: 45891 | K95: KOTHE AULAKH | L95: VILLAGE JETHUKE,BATHINDA | M95: PIN:151103,PUNJAB,INDIA | N95: 202509058756 | O95: 45889
A96: 1494 | B96: HUSSAIN MOHAMMED | C96: 45864 | D96: EPPING, AUSTRALIA | E96: AU2065656552325 | F96: M | G96: MOHAMMED HASAN | H96: LUBNA | I96: C7186512 | J96: 45891 | K96: 17-3-3/1/86/A,AZMATH NAGAR | L96: YAKUTPURA,HYDERABAD | M96: PIN:500023,TELANGANA,INDIA | N96: 202509058774 | O96: 45889
A97: 1495 | B97: KUDRAT KAUR KALER | C97: 45776 | D97: BALLARAT CENTRAL, AUSTRALIA | E97: AU2065656553325 | F97: F | G97: TALWINDER SINGH | H97: SIMARJIT KAUR | I97: Y5057483 | J97: 45891 | K97: 158 | L97: V.P.O - SARWALI,GURDASPUR | M97: PIN:143511,PUNJAB,INDIA | N97: 202509058394 | O97: 45888
A98: 1496 | B98: TAJ SINGH | C98: 45769 | D98: BERWICK, AUSTRALIA | E98: AU2065656554525 | F98: M | G98: SUKHWINDER SINGH | H98: KULDEEP KAUR BRAR | I98: X5414710 | J98: 45891 | K98: 280 | L98: CHIDA,MOGA | M98: PIN:142049,PUNJAB,INDIA | N98: 202509058925 | O98: 45890
...

Sheet DocuMateSRC
A1: Serial | B1: File_Number | C1: Name | D1: Sex | E1: Name_of_the_Father | F1: Name_of_the_Mother | G1: When_and_where_born | H1: Description_and_residence_of_informant | I1: Registration_date | J1: MHA_File_And_date | K1: STATUS | L1: Date_Printed | M1: Date_Issued | N1: Sighning_Authority
A2: =Sheet1!A2 & "/" & "2025" -> 1400/2025 | B2: =Sheet1!E2 -> AU2065646519525 | C2: =UPPER(Sheet1!B2) -> SHRIJEET SARANG HINGASPURE | D2: =IF(Sheet1!F2="F","FEMALE","MALE") -> MALE | E2: =UPPER(Sheet1!G2) -> SARANG SANJAY HINGASPURE | F2: =UPPER(Sheet1!H2) -> PAYAL ARUN GULHANE | G2: =TEXT(Sheet1!C2,"dd/mm/yyyy") & "," & Sheet1!D2 -> 13/07/2025,PARKVILLE, AUSTRALIA | H2: =UPPER(Sheet1!K2 & "," & Sheet1!L2 & "," & Sheet1!M2) -> PLOT NO 41 VIVEKANAND COLONY,RUKHMINI NAGAR,AMRAVATI,AMRAVATI CITY,PIN:444606,MAHARASHTRA,INDIA | I2: =Sheet1!J2 -> 45880 | J2: =Sheet1!N2 & "," & TEXT(Sheet1!O2,"dd/mm/yy") -> 202509055366,06/08/25 | K2: IN PROCESS | L2: 22/03/2026 | M2: 45925 | N2: MANISH KATARIA, VICE CONSUL
A3: =Sheet1!A3 & "/" & "2025" -> 1401/2025 | B3: =Sheet1!E3 -> AU206564652032 | C3: =UPPER(Sheet1!B3) -> IZHAAN MOHAMMED SHAIK | D3: =IF(Sheet1!F3="F","FEMALE","MALE") -> MALE | E3: =UPPER(Sheet1!G3) -> ABDUL ASIF | F3: =UPPER(Sheet1!H3) -> SANIA ANJUM SHAIK | G3: =TEXT(Sheet1!C3,"dd/mm/yyyy") & "," & Sheet1!D3 -> 12/06/2025,WERIBEE, AUSTRALIA | H3: =UPPER(Sheet1!K3 & "," & Sheet1!L3 & "," & Sheet1!M3) -> 9-60-60,SUBBARAO STREET,ISLAMPET,VIJAYAWADA,NTR DISTRICT,PIN:520001,ANDHRA PRADESH,INDIA | I3: =Sheet1!J3 -> 45880 | J3: =Sheet1!N3 & "," & TEXT(Sheet1!O3,"dd/mm/yy") -> 202509053616,31/07/25 | K3: IN PROCESS | L3: 22/03/2026 | M3: 45925 | N3: MANISH KATARIA, VICE CONSUL
A4: =Sheet1!A4 & "/" & "2025" -> 1402/2025 | B4: =Sheet1!E4 -> AU2065646520525 | C4: =UPPER(Sheet1!B4) -> MEHAR DAMANI | D4: =IF(Sheet1!F4="F","FEMALE","MALE") -> FEMALE | E4: =UPPER(Sheet1!G4) -> JAI KISHAN | F4: =UPPER(Sheet1!H4) -> JYOTI | G4: =TEXT(Sheet1!C4,"dd/mm/yyyy") & "," & Sheet1!D4 -> 14/03/2025,ST ALBANS, AUSTRALIA | H4: =UPPER(Sheet1!K4 & "," & Sheet1!L4 & "," & Sheet1!M4) -> WARD NO.5,PADAMPUR,SRI GANGANAGAR,PIN:335041,RAJASTHAN,INDIA | I4: =Sheet1!J4 -> 45880 | J4: =Sheet1!N4 & "," & TEXT(Sheet1!O4,"dd/mm/yy") -> 202509051511,23/07/25 | K4: IN PROCESS | L4: 22/03/2026 | M4: 45925 | N4: MANISH KATARIA, VICE CONSUL
A5: =Sheet1!A5 & "/" & "2025" -> 1403/2025 | B5: =Sheet1!E5 -> AU2065646520925 | C5: =UPPER(Sheet1!B5) -> ZOHAN VANIB MANSURI | D5: =IF(Sheet1!F5="F","FEMALE","MALE") -> MALE | E5: =UPPER(Sheet1!G5) -> VANIB MOHMEDHARUN MANSURI | F5: =UPPER(Sheet1!H5) -> RIZA VANIB MANSURI | G5: =TEXT(Sheet1!C5,"dd/mm/yyyy") & "," & Sheet1!D5 -> 17/07/2025,HOBART, AUSTRALIA | H5: =UPPER(Sheet1!K5 & "," & Sheet1!L5 & "," & Sheet1!M5) -> 74 MAULANA AZAD PARK SOC.,OPP AEGRO PETROL PUMP,SARKHEJ ROAD,JUHAPURA,AHMEDABAD,PIN:380055,GUJARAT,INDIA | I5: =Sheet1!J5 -> 45880 | J5: =Sheet1!N5 & "," & TEXT(Sheet1!O5,"dd/mm/yy") -> 202509053619,31/07/25 | K5: IN PROCESS | L5: 22/03/2026 | M5: 45925 | N5: MANISH KATARIA, VICE CONSUL
A6: =Sheet1!A6 & "/" & "2025" -> 1404/2025 | B6: =Sheet1!E6 -> AU2065646521325 | C6: =UPPER(Sheet1!B6) -> ARJAN SINGH SEKHON | D6: =IF(Sheet1!F6="F","FEMALE","MALE") -> MALE | E6: =UPPER(Sheet1!G6) -> HARKAMALPREET SINGH | F6: =UPPER(Sheet1!H6) -> ARSHPREET KAUR | G6: =TEXT(Sheet1!C6,"dd/mm/yyyy") & "," & Sheet1!D6 -> 23/04/2025,WERRIBEE, AUSTRALIA | H6: =UPPER(Sheet1!K6 & "," & Sheet1!L6 & "," & Sheet1!M6) -> VILLAGE DHENTHAL,TEHSIL SAMANA,PATIALA,PIN:147101,PUNJAB,INDIA | I6: =Sheet1!J6 -> 45880 | J6: =Sheet1!N6 & "," & TEXT(Sheet1!O6,"dd/mm/yy") -> 202509041249,16/06/25 | K6: IN PROCESS | L6: 22/03/2026 | M6: 45925 | N6: MANISH KATARIA, VICE CONSUL
A7: =Sheet1!A7 & "/" & "2025" -> 1405/2025 | B7: =Sheet1!E7 -> AU2065646521525 | C7: =UPPER(Sheet1!B7) -> LOKESH CHOWDARY JAMMIGUMPULA | D7: =IF(Sheet1!F7="F","FEMALE","MALE") -> MALE | E7: =UPPER(Sheet1!G7) -> HARIKRISHNA JAMMIGUMPULA | F7: =UPPER(Sheet1!H7) -> NAVYA VADLAMUDI | G7: =TEXT(Sheet1!C7,"dd/mm/yyyy") & "," & Sheet1!D7 -> 26/05/2025,BACCHUS MARSH, AUSTRALIA | H7: =UPPER(Sheet1!K7 & "," & Sheet1!L7 & "," & Sheet1!M7) -> H.NO: 3-54,KOTHAPALEM VILLAGE,MACHAVARAM MD,PALNADU,PIN:522435,ANDHRA PRADESH,INDIA | I7: =Sheet1!J7 -> 45880 | J7: =Sheet1!N7 & "," & TEXT(Sheet1!O7,"dd/mm/yy") -> 202509055812,08/08/25 | K7: IN PROCESS | L7: 22/03/2026 | M7: 45925 | N7: MANISH KATARIA, VICE CONSUL
A8: =Sheet1!A8 & "/" & "2025" -> 1406/2025 | B8: =Sheet1!E8 -> AU2065649408125 | C8: =UPPER(Sheet1!B8) -> AAYRA VERMA | D8: =IF(Sheet1!F8="F","FEMALE","MALE") -> FEMALE | E8: =UPPER(Sheet1!G8) -> PARAMJIT SINGH | F8: =UPPER(Sheet1!H8) -> ARTI | G8: =TEXT(Sheet1!C8,"dd/mm/yyyy") & "," & Sheet1!D8 -> 05/02/2025,EPPING, AUSTRALIA | H8: =UPPER(Sheet1!K8 & "," & Sheet1!L8 & "," & Sheet1!M8) -> H NO 20,UKSI JATTAN TEH RAJPURA,PATIALA,PIN:140401,PUNJAB,INDIA | I8: =Sheet1!J8 -> 45883 | J8: =Sheet1!N8 & "," & TEXT(Sheet1!O8,"dd/mm/yy") -> 202509042789,21/06/25 | K8: IN PROCESS | L8: 22/03/2026 | M8: 45925 | N8: MANISH KATARIA, VICE CONSUL
A9: =Sheet1!A9 & "/" & "2025" -> 1407/2025 | B9: =Sheet1!E9 -> AU2065649408725 | C9: =UPPER(Sheet1!B9) -> VANDAN MIHIRKUMAR PAREKH | D9: =IF(Sheet1!F9="F","FEMALE","MALE") -> MALE | E9: =UPPER(Sheet1!G9) -> MIHIRKUMAR NIRANJANKUMAR PAREKH | F9: =UPPER(Sheet1!H9) -> URVISHABEN MIHIRKUMAR PAREKH | G9: =TEXT(Sheet1!C9,"dd/mm/yyyy") & "," & Sheet1!D9 -> 14/12/2024,CLAYTON, AUSTRALIA | H9: =UPPER(Sheet1!K9 & "," & Sheet1!L9 & "," & Sheet1!M9) -> B/9 SATKARPARK SOCIETY RAMTALAWADI ROAD,NADIAD,KHEDA,PIN:387002,GUJARAT,INDIA | I9: =Sheet1!J9 -> 45883 | J9: =Sheet1!N9 & "," & TEXT(Sheet1!O9,"dd/mm/yy") -> 202509055846,08/08/25 | K9: IN PROCESS | L9: 22/03/2026 | M9: 45925 | N9: MANISH KATARIA, VICE CONSUL
A10: =Sheet1!A10 & "/" & "2025" -> 1408/2025 | B10: =Sheet1!E10 -> AU2065649409125 | C10: =UPPER(Sheet1!B10) -> PRABHDOOR SINGH KHALSA | D10: =IF(Sheet1!F10="F","FEMALE","MALE") -> MALE | E10: =UPPER(Sheet1!G10) -> GURSEWAK SINGH | F10: =UPPER(Sheet1!H10) -> RAMANJIT KAUR | G10: =TEXT(Sheet1!C10,"dd/mm/yyyy") & "," & Sheet1!D10 -> 10/06/2025,HOBART, AUSTRALIA | H10: =UPPER(Sheet1!K10 & "," & Sheet1!L10 & "," & Sheet1!M10) -> V.P.O,NANDA CHAUR,HOSHIARPUR,PIN:146114,PUNJAB,INDIA | I10: =Sheet1!J10 -> 45883 | J10: =Sheet1!N10 & "," & TEXT(Sheet1!O10,"dd/mm/yy") -> 202509053355,30/07/25 | K10: IN PROCESS | L10: 22/03/2026 | M10: 45925 | N10: MANISH KATARIA, VICE CONSUL
A11: =Sheet1!A11 & "/" & "2025" -> 1409/2025 | B11: =Sheet1!E11 -> AU2065649409725 | C11: =UPPER(Sheet1!B11) -> AJIT SINGH SIDHU | D11: =IF(Sheet1!F11="F","FEMALE","MALE") -> MALE | E11: =UPPER(Sheet1!G11) -> SHAGANDEEP SINGH SIDHU | F11: =UPPER(Sheet1!H11) -> BAVANPREET KAUR | G11: =TEXT(Sheet1!C11,"dd/mm/yyyy") & "," & Sheet1!D11 -> 18/11/2024,ST SLBANS, AUSTRALIA | H11: =UPPER(Sheet1!K11 & "," & Sheet1!L11 & "," & Sheet1!M11) -> V.P.O QILA HAKIMA,DHURI,SANGRUR,PIN:148034,PUNJAB,INDIA | I11: =Sheet1!J11 -> 45883 | J11: =Sheet1!N11 & "," & TEXT(Sheet1!O11,"dd/mm/yy") -> 202509044804,28/06/25 | K11: IN PROCESS | L11: 22/03/2026 | M11: 45925 | N11: MANISH KATARIA, VICE CONSUL
A12: =Sheet1!A12 & "/" & "2025" -> 1410/2025 | B12: =Sheet1!E12 -> AU2065649409925 | C12: =UPPER(Sheet1!B12) -> SEHBAZ SINGH | D12: =IF(Sheet1!F12="F","FEMALE","MALE") -> MALE | E12: =UPPER(Sheet1!G12) -> HARPREET SINGH | F12: =UPPER(Sheet1!H12) -> REENA TALWAR | G12: =TEXT(Sheet1!C12,"dd/mm/yyyy") & "," & Sheet1!D12 -> 10/05/2025,ST ALBANS, AUSTRALIA | H12: =UPPER(Sheet1!K12 & "," & Sheet1!L12 & "," & Sheet1!M12) -> VPO JANDIALA ,PATTI RAM KI,TEH. PHILLAUR,JALANDHAR,PIN:144033,PUNJAB,INDIA | I12: =Sheet1!J12 -> 45883 | J12: =Sheet1!N12 & "," & TEXT(Sheet1!O12,"dd/mm/yy") -> 202509052252,26/07/25 | K12: IN PROCESS | L12: 22/03/2026 | M12: 45925 | N12: MANISH KATARIA, VICE CONSUL
A13: =Sheet1!A13 & "/" & "2025" -> 1411/2025 | B13: =Sheet1!E13 -> AU2065649410725 | C13: =UPPER(Sheet1!B13) -> SHAIVI JAGLAN | D13: =IF(Sheet1!F13="F","FEMALE","MALE") -> FEMALE | E13: =UPPER(Sheet1!G13) -> SUMIT KUMAR | F13: =UPPER(Sheet1!H13) -> VEENITA RAJ | G13: =TEXT(Sheet1!C13,"dd/mm/yyyy") & "," & Sheet1!D13 -> 20/01/2025,EPPING, AUSTRALIA | H13: =UPPER(Sheet1!K13 & "," & Sheet1!L13 & "," & Sheet1!M13) -> VPO KURANA(54),ISRANA,PANIPAT,PIN:132107,HARYANA,INDIA | I13: =Sheet1!J13 -> 45883 | J13: =Sheet1!N13 & "," & TEXT(Sheet1!O13,"dd/mm/yy") -> 202509041529,17/06/25 | K13: IN PROCESS | L13: 22/03/2026 | M13: 45925 | N13: MANISH KATARIA, VICE CONSUL
... A406: =Sheet1!A406 & "/" & "2025" -> 1804/2025 | B406: =Sheet1!E406 -> AU2065867422425 | C406: =UPPER(Sheet1!B406) -> RUDVED REDDY KOLACHI | D406: =IF(Sheet1!F406="F","FEMALE","MALE") -> MALE | E406: =UPPER(Sheet1!G406) -> ROHIT REDDY KOLACHI | F406: =UPPER(Sheet1!H406) -> NAVYA REDDY BOGURAMPET | G406: =TEXT(Sheet1!C406,"dd/mm/yyyy") & "," & Sheet1!D406 -> 09/07/2025,GOSFORD, AUSTRALIA | H406: =UPPER(Sheet1!K406 & "," & Sheet1!L406 & "," & Sheet1!M406) -> H NO 4-42,ALMASGUDA,SAROORNAGAR MANDAL,RANGAREDDY,PIN:500058,TELANGANA,INDIA | I406: =Sheet1!J406 -> 45958 | J406: =Sheet1!N406 & "," & TEXT(Sheet1!O406,"dd/mm/yy") -> 202509072799,14/10/25 | K406: PRINTED | L406: 22/03/2026 | M406: 45959 | N406: MANISH KATARIA, VICE CONSUL
A407: =Sheet1!A407 & "/" & "2025" -> 1805/2025 | B407: =Sheet1!E407 -> AU2065867422625 | C407: =UPPER(Sheet1!B407) -> SADAA KAUR | D407: =IF(Sheet1!F407="F","FEMALE","MALE") -> FEMALE | E407: =UPPER(Sheet1!G407) -> SAHIL SINGH | F407: =UPPER(Sheet1!H407) -> SEHAJPREET KAUR | G407: =TEXT(Sheet1!C407,"dd/mm/yyyy") & "," & Sheet1!D407 -> 10/01/2025,ST ALBANS , AUSTRALIA | H407: =UPPER(Sheet1!K407 & "," & Sheet1!L407 & "," & Sheet1!M407) -> VPO. MAAN SANDWAL,TEH. BATALA,GURDASPUR,PIN:143602,PUNJAB,INDIA | I407: =Sheet1!J407 -> 45958 | J407: =Sheet1!N407 & "," & TEXT(Sheet1!O407,"dd/mm/yy") -> 202509072787,14/10/25 | K407: PRINTED | L407: 22/03/2026 | M407: 15/12/2025 | N407: MANISH KATARIA, VICE CONSUL
A408: =Sheet1!A408 & "/" & "2025" -> 1806/2025 | B408: =Sheet1!E408 -> AU2065698248925 | C408: =UPPER(Sheet1!B408) -> VAAYU SINGH SANSANWAL | D408: =IF(Sheet1!F408="F","FEMALE","MALE") -> MALE | E408: =UPPER(Sheet1!G408) -> ARJUN SINGH SANSANWAL | F408: =UPPER(Sheet1!H408) -> JYOTI SIWAS | G408: =TEXT(Sheet1!C408,"dd/mm/yyyy") & "," & Sheet1!D408 -> 30/05/2025,EPPING , AUSTRALIA | H408: =UPPER(Sheet1!K408 & "," & Sheet1!L408 & "," & Sheet1!M408) -> D-41 NEELAMBER APARTMENT,RANI BAGH,DELHI,PIN:110034,DELHI,INDIA | I408: =Sheet1!J408 -> 45961 | J408: =Sheet1!N408 & "," & TEXT(Sheet1!O408,"dd/mm/yy") -> 202509068879,29/09/25 | K408: PRINTED | L408: 22/03/2026 | M408: 15/12/2025 | N408: MANISH KATARIA, VICE CONSUL
A409: =Sheet1!A409 & "/" & "2025" -> 1807/2025 | B409: =Sheet1!E409 -> AU2065867423025 | C409: =UPPER(Sheet1!B409) -> ADWITHA MARAR | D409: =IF(Sheet1!F409="F","FEMALE","MALE") -> FEMALE | E409: =UPPER(Sheet1!G409) -> ARJUN VASUDEVAN MARAR | F409: =UPPER(Sheet1!H409) -> AMRITHA PARIYARATH | G409: =TEXT(Sheet1!C409,"dd/mm/yyyy") & "," & Sheet1!D409 -> 19/08/2025,WERIBEE, AUSTRALIA | H409: =UPPER(Sheet1!K409 & "," & Sheet1!L409 & "," & Sheet1!M409) -> KRISHNANJALI MARATH,KOTTAYI PO,KOTTAYI,PALAKKAD,PIN:678572,KERALA,INDIA | I409: =Sheet1!J409 -> 45964 | J409: =Sheet1!N409 & "," & TEXT(Sheet1!O409,"dd/mm/yy") -> 202509070414,05/10/25 | K409: PRINTED | L409: 22/03/2026 | M409: 15/12/2025 | N409: MANISH KATARIA, VICE CONSUL
A410: =Sheet1!A410 & "/" & "2025" -> 1808/2025 | B410: =Sheet1!E410 -> AU2065867423225 | C410: =UPPER(Sheet1!B410) -> MEHTAB SINGH | D410: =IF(Sheet1!F410="F","FEMALE","MALE") -> MALE | E410: =UPPER(Sheet1!G410) -> HARJINDER SINGH | F410: =UPPER(Sheet1!H410) -> GURPREET KAUR | G410: =TEXT(Sheet1!C410,"dd/mm/yyyy") & "," & Sheet1!D410 -> 07/09/2025,GEELONG , AUSTRALIA | H410: =UPPER(Sheet1!K410 & "," & Sheet1!L410 & "," & Sheet1!M410) -> VPO,BHATTIKE,AMRITSAR,PIN:143116,PUNJAB,INDIA | I410: =Sheet1!J410 -> 45964 | J410: =Sheet1!N410 & "," & TEXT(Sheet1!O410,"dd/mm/yy") -> 202509072768,14/10/25 | K410: PRINTED | L410: 22/03/2026 | M410: 15/12/2025 | N410: MANISH KATARIA, VICE CONSUL
A411: =Sheet1!A411 & "/" & "2025" -> 1809/2025 | B411: =Sheet1!E411 -> AU2065867423425 | C411: =UPPER(Sheet1!B411) -> UPKAR KAUR BRAR | D411: =IF(Sheet1!F411="F","FEMALE","MALE") -> FEMALE | E411: =UPPER(Sheet1!G411) -> ARSHDEEP SINGH | F411: =UPPER(Sheet1!H411) -> GURMINDER KAUR | G411: =TEXT(Sheet1!C411,"dd/mm/yyyy") & "," & Sheet1!D411 -> 27/08/2025,ST ALBANS , AUSTRALIA | H411: =UPPER(Sheet1!K411 & "," & Sheet1!L411 & "," & Sheet1!M411) -> MIRZA PATTI,VPO. PANJGRAIN KALAN,FARIDKOT,PIN:151207,PUNJAB,INDIA | I411: =Sheet1!J411 -> 45964 | J411: =Sheet1!N411 & "," & TEXT(Sheet1!O411,"dd/mm/yy") -> 202509073054,15/10/25 | K411: PRINTED | L411: 22/03/2026 | M411: 15/12/2025 | N411: MANISH KATARIA, VICE CONSUL
A412: =Sheet1!A412 & "/" & "2025" -> 1810/2025 | B412: =Sheet1!E412 -> AU2065867423625 | C412: =UPPER(Sheet1!B412) -> NIVAAN RANDHAWA | D412: =IF(Sheet1!F412="F","FEMALE","MALE") -> MALE | E412: =UPPER(Sheet1!G412) -> GURJEET SINGH | F412: =UPPER(Sheet1!H412) -> KIRANDEEP KAUR | G412: =TEXT(Sheet1!C412,"dd/mm/yyyy") & "," & Sheet1!D412 -> 29/05/2025,WERIBEE, AUSTRALIA | H412: =UPPER(Sheet1!K412 & "," & Sheet1!L412 & "," & Sheet1!M412) -> VILL BHAMBRI,THE KHAMANO,FATEHGARH SAHIB,PIN:141801,PUNJAB,INDIA | I412: =Sheet1!J412 -> 45964 | J412: =Sheet1!N412 & "," & TEXT(Sheet1!O412,"dd/mm/yy") -> 202509071868,10/10/25 | K412: PRINTED | L412: 22/03/2026 | M412: 15/12/2025 | N412: MANISH KATARIA, VICE CONSUL
A413: =Sheet1!A413 & "/" & "2025" -> 1811/2025 | B413: =Sheet1!E413 -> AU2065867423825 | C413: =UPPER(Sheet1!B413) -> SHRIYANSH KONABOINA | D413: =IF(Sheet1!F413="F","FEMALE","MALE") -> MALE | E413: =UPPER(Sheet1!G413) -> NAVEEN KUMAR KONABOINA | F413: =UPPER(Sheet1!H413) -> AISHWARYA LAXMI THOTA | G413: =TEXT(Sheet1!C413,"dd/mm/yyyy") & "," & Sheet1!D413 -> 01/02/2025,ST ALBANS , AUSTRALIA | H413: =UPPER(Sheet1!K413 & "," & Sheet1!L413 & "," & Sheet1!M413) -> 58-17,SRIRAM NAGAR COLONY,CHINTAL,HMT TOWSHIP,QUTHUBULLAPUR,MEDCHAL,PIN:500054,TELANGANA,INDIA | I413: =Sheet1!J413 -> 45964 | J413: =Sheet1!N413 & "," & TEXT(Sheet1!O413,"dd/mm/yy") -> 202509070962,07/10/25 | K413: PRINTED | L413: 22/03/2026 | M413: 15/12/2025 | N413: MANISH KATARIA, VICE CONSUL
A414: =Sheet1!A414 & "/" & "2025" -> 1812/2025 | B414: =Sheet1!E414 -> AU2065867424025 | C414: =UPPER(Sheet1!B414) -> SHANEL KAUR SARAO | D414: =IF(Sheet1!F414="F","FEMALE","MALE") -> FEMALE | E414: =UPPER(Sheet1!G414) -> KULBIR SINGH SARAO | F414: =UPPER(Sheet1!H414) -> SUKHDEEP KAUR SARAO | G414: =TEXT(Sheet1!C414,"dd/mm/yyyy") & "," & Sheet1!D414 -> 02/09/2025,SHEPPARTON, AUSTRALIA | H414: =UPPER(Sheet1!K414 & "," & Sheet1!L414 & "," & Sheet1!M414) -> VILL BABBANPUR PO BHASAUR,TEH. DHURI,SANGRUR,PIN:148024,PUNJAB,INDIA | I414: =Sheet1!J414 -> 45964 | J414: =Sheet1!N414 & "," & TEXT(Sheet1!O414,"dd/mm/yy") -> 202509073447,16/10/25 | K414: PRINTED | L414: 22/03/2026 | M414: 15/12/2025 | N414: MANISH KATARIA, VICE CONSUL
A415: =Sheet1!A415 & "/" & "2025" -> 1813/2025 | B415: =Sheet1!E415 -> AU2065869755625 | C415: =UPPER(Sheet1!B415) -> DHARSHIK PEDDI | D415: =IF(Sheet1!F415="F","FEMALE","MALE") -> MALE | E415: =UPPER(Sheet1!G415) -> DIXITH PEDDI | F415: =UPPER(Sheet1!H415) -> HARINI AMBALLA | G415: =TEXT(Sheet1!C415,"dd/mm/yyyy") & "," & Sheet1!D415 -> 02/09/2025,CLAYTON , AUSTRALIA | H415: =UPPER(Sheet1!K415 & "," & Sheet1!L415 & "," & Sheet1!M415) -> 2-91,CHOUTPALLY,KAMMARPALLY,NIZAMABAD,PIN:503308,TELANGANA,INDIA | I415: =Sheet1!J415 -> 45964 | J415: =Sheet1!N415 & "," & TEXT(Sheet1!O415,"dd/mm/yy") -> 202509073448,16/10/25 | K415: PRINTED | L415: 22/03/2026 | M415: 15/12/2025 | N415: MANISH KATARIA, VICE CONSUL
A416: =Sheet1!A416 & "/" & "2025" -> 1814/2025 | B416: =Sheet1!E416 -> AU2065869756425 | C416: =UPPER(Sheet1!B416) -> HARFATEH SINGH | D416: =IF(Sheet1!F416="F","FEMALE","MALE") -> MALE | E416: =UPPER(Sheet1!G416) -> HARDEEP SINGH | F416: =UPPER(Sheet1!H416) -> VARINDER KAUR | G416: =TEXT(Sheet1!C416,"dd/mm/yyyy") & "," & Sheet1!D416 -> 18/06/2025,ST ALBANS , AUSTRALIA | H416: =UPPER(Sheet1!K416 & "," & Sheet1!L416 & "," & Sheet1!M416) -> VILL.BANGANWALI PO BARDWAL,TEH DHURI,SANGRUR,PIN:148024,PUNJAB,INDIA | I416: =Sheet1!J416 -> 45964 | J416: =Sheet1!N416 & "," & TEXT(Sheet1!O416,"dd/mm/yy") -> 202509065662,16/09/25 | K416: PRINTED | L416: 22/03/2026 | M416: 15/12/2025 | N416: MANISH KATARIA, VICE CONSUL
A417: =Sheet1!A417 & "/" & "2025" -> 1815/2025 | B417: =Sheet1!E417 -> AU2065869756825 | C417: =UPPER(Sheet1!B417) -> JAHAAN SINGH GREWAL | D417: =IF(Sheet1!F417="F","FEMALE","MALE") -> MALE | E417: =UPPER(Sheet1!G417) -> NAVTEJ SINGH GREWAL | F417: =UPPER(Sheet1!H417) -> MANDEEP KAUR | G417: =TEXT(Sheet1!C417,"dd/mm/yyyy") & "," & Sheet1!D417 -> 11/03/2025,HEIDELBERG , AUSTRALIA | H417: =UPPER(Sheet1!K417 & "," & Sheet1!L417 & "," & Sheet1!M417) -> VILLAGE - DHANER P.O. CHAK BHAI KA,P.S. MEHAL KALAN,BARNALA,PIN:148104,PUNJAB,INDIA | I417: =Sheet1!J417 -> 45964 | J417: =Sheet1!N417 & "," & TEXT(Sheet1!O417,"dd/mm/yy") -> 202509072294,12/10/25 | K417: PRINTED | L417: 22/03/2026 | M417: 15/12/2025 | N417: MANISH KATARIA, VICE CONSUL
A418: =Sheet1!A418 & "/" & "2025" -> 1816/2025 | B418: =Sheet1!E418 -> AU2065869757025 | C418: =UPPER(Sheet1!B418) -> JASSICA KAUR MAAN | D418: =IF(Sheet1!F418="F","FEMALE","MALE") -> FEMALE | E418: =UPPER(Sheet1!G418) -> JAGDEV SINGH MAAN | F418: =UPPER(Sheet1!H418) -> JASPREET KAUR MAAN | G418: =TEXT(Sheet1!C418,"dd/mm/yyyy") & "," & Sheet1!D418 -> 21/07/2025,KINGSWOOD, AUSTRALIA | H418: =UPPER(Sheet1!K418 & "," & Sheet1!L418 & "," & Sheet1!M418) -> VPO KABUL SHAH KHUBAN,FAZILKA,FAZILKA,PIN:152123,PUNJAB,INDIA | I418: =Sheet1!J418 -> 45964 | J418: =Sheet1!N418 & "," & TEXT(Sheet1!O418,"dd/mm/yy") -> 202509070831,07/10/25 | K418: PRINTED | L418: 22/03/2026 | M418: 15/12/2025 | N418: MANISH KATARIA, VICE CONSUL
... A728: =Sheet1!A728 & "/" & "2025" -> 2126/2025 | B728: =Sheet1!E728 -> AU2065914961625 | C728: =UPPER(Sheet1!B728) -> HAZEL MARIE JOBIN | D728: =IF(Sheet1!F728="F","FEMALE","MALE") -> FEMALE | E728: =UPPER(Sheet1!G728) -> JOBIN THOMAS | F728: =UPPER(Sheet1!H728) -> TREESA JACOB | G728: =TEXT(Sheet1!C728,"dd/mm/yyyy") & "," & Sheet1!D728 -> 25/08/2025,BALLARAT CENTRAL, AUSTRALIA | H728: =UPPER(Sheet1!K728 & "," & Sheet1!L728 & "," & Sheet1!M728) -> AKKATHOTTIYIL HOUSE PANDIPPARA P.O,EETTIKAVALA,IDUKKI,PIN:685609,KERALA,INDIA | I728: =Sheet1!J728 -> 46020 | J728: =Sheet1!N728 & "," & TEXT(Sheet1!O728,"dd/mm/yy") -> 202509070860,07/10/25 | K728: PRINTED | L728: 22/03/2026 | M728: 30/12/2025 | N728: MANISH KATARIA, VICE CONSUL

Sheet Sheet5
A1: Date | B1: Count | C1: Manual | D1: DocuMate | E1: Percentage | F1: Mach
A2: 45925 | B2: 235 | C2: =B2*315 -> 74025 | D2: =B2*0.1 -> 23.5 | E2: =((Table5[[#This Row],[Manual]]-Table5[[#This Row],[DocuMate]])/Table5[[#This Row],[Manual]])*100 -> 99.968254 | F2: =(Table5[[#This Row],[Manual]]/Table5[[#This Row],[DocuMate]]) -> 3150
A3: 45937 | B3: 46 | C3: =B3*315 -> 14490 | D3: =B3*0.1 -> 4.6 | E3: =((Table5[[#This Row],[Manual]]-Table5[[#This Row],[DocuMate]])/Table5[[#This Row],[Manual]])*100 -> 99.968254 | F3: =(Table5[[#This Row],[Manual]]/Table5[[#This Row],[DocuMate]]) -> 3150
A4: 45944 | B4: 45 | C4: =B4*315 -> 14175 | D4: =B4*0.1 -> 4.5 | E4: =((Table5[[#This Row],[Manual]]-Table5[[#This Row],[DocuMate]])/Table5[[#This Row],[Manual]])*100 -> 99.968254 | F4: =(Table5[[#This Row],[Manual]]/Table5[[#This Row],[DocuMate]]) -> 3150
A5: 45959 | B5: 77 | C5: =B5*315 -> 24255 | D5: =B5*0.1 -> 7.7 | E5: =((Table5[[#This Row],[Manual]]-Table5[[#This Row],[DocuMate]])/Table5[[#This Row],[Manual]])*100 -> 99.968254 | F5: =(Table5[[#This Row],[Manual]]/Table5[[#This Row],[DocuMate]]) -> 3150
A6: 46006 | B6: 251 | C6: =B6*315 -> 79065 | D6: =B6*0.1 -> 25.1 | E6: =((Table5[[#This Row],[Manual]]-Table5[[#This Row],[DocuMate]])/Table5[[#This Row],[Manual]])*100 -> 99.968254 | F6: =(Table5[[#This Row],[Manual]]/Table5[[#This Row],[DocuMate]]) -> 3150
A7: 46021 | B7: 17 | C7: =B7*315 -> 5355 | D7: =B7*0.1 -> 1.7 | E7: =((Table5[[#This Row],[Manual]]-Table5[[#This Row],[DocuMate]])/Table5[[#This Row],[Manual]])*100 -> 99.968254 | F7: =(Table5[[#This Row],[Manual]]/Table5[[#This Row],[DocuMate]]) -> 3150

Sheet Sheet7
A2: Sex | B2: Count of Sex
A3: MALE | B3: 382
A4: FEMALE | B4: 345
A5: Grand Total | B5: 727
